[2020-04-16 18:28:16,151] {/Library/Python/2.7/site-packages/flask/app.py:1891} ERROR - Exception on /person [POST]
Traceback (most recent call last):
  File "/Library/Python/2.7/site-packages/flask/app.py", line 1949, in full_dispatch_request
    rv = self.dispatch_request()
  File "/Library/Python/2.7/site-packages/flask/app.py", line 1935, in dispatch_request
    return self.view_functions[rule.endpoint](**req.view_args)
  File "/Library/Python/2.7/site-packages/flask_restful/__init__.py", line 458, in wrapper
    resp = resource(*args, **kwargs)
  File "/Library/Python/2.7/site-packages/flask/views.py", line 89, in view
    return self.dispatch_request(*args, **kwargs)
  File "/Library/Python/2.7/site-packages/flask_restful/__init__.py", line 573, in dispatch_request
    resp = meth(*args, **kwargs)
  File "/Users/rachmankamil/Python/rest-training-batch-3/day-2.2-database/blueprints/person/resources.py", line 42, in post
    db.session.commit()
  File "/Library/Python/2.7/site-packages/sqlalchemy/orm/scoping.py", line 162, in do
    return getattr(self.registry(), name)(*args, **kwargs)
  File "/Library/Python/2.7/site-packages/sqlalchemy/orm/session.py", line 1027, in commit
    self.transaction.commit()
  File "/Library/Python/2.7/site-packages/sqlalchemy/orm/session.py", line 494, in commit
    self._prepare_impl()
  File "/Library/Python/2.7/site-packages/sqlalchemy/orm/session.py", line 473, in _prepare_impl
    self.session.flush()
  File "/Library/Python/2.7/site-packages/sqlalchemy/orm/session.py", line 2459, in flush
    self._flush(objects)
  File "/Library/Python/2.7/site-packages/sqlalchemy/orm/session.py", line 2597, in _flush
    transaction.rollback(_capture_exception=True)
  File "/Library/Python/2.7/site-packages/sqlalchemy/util/langhelpers.py", line 68, in __exit__
    compat.reraise(exc_type, exc_value, exc_tb)
  File "/Library/Python/2.7/site-packages/sqlalchemy/orm/session.py", line 2557, in _flush
    flush_context.execute()
  File "/Library/Python/2.7/site-packages/sqlalchemy/orm/unitofwork.py", line 422, in execute
    rec.execute(self)
  File "/Library/Python/2.7/site-packages/sqlalchemy/orm/unitofwork.py", line 589, in execute
    uow,
  File "/Library/Python/2.7/site-packages/sqlalchemy/orm/persistence.py", line 245, in save_obj
    insert,
  File "/Library/Python/2.7/site-packages/sqlalchemy/orm/persistence.py", line 1138, in _emit_insert_statements
    statement, params
  File "/Library/Python/2.7/site-packages/sqlalchemy/engine/base.py", line 988, in execute
    return meth(self, multiparams, params)
  File "/Library/Python/2.7/site-packages/sqlalchemy/sql/elements.py", line 287, in _execute_on_connection
    return connection._execute_clauseelement(self, multiparams, params)
  File "/Library/Python/2.7/site-packages/sqlalchemy/engine/base.py", line 1107, in _execute_clauseelement
    distilled_params,
  File "/Library/Python/2.7/site-packages/sqlalchemy/engine/base.py", line 1248, in _execute_context
    e, statement, parameters, cursor, context
  File "/Library/Python/2.7/site-packages/sqlalchemy/engine/base.py", line 1466, in _handle_dbapi_exception
    util.raise_from_cause(sqlalchemy_exception, exc_info)
  File "/Library/Python/2.7/site-packages/sqlalchemy/util/compat.py", line 398, in raise_from_cause
    reraise(type(exception), exception, tb=exc_tb, cause=cause)
  File "/Library/Python/2.7/site-packages/sqlalchemy/engine/base.py", line 1244, in _execute_context
    cursor, statement, parameters, context
  File "/Library/Python/2.7/site-packages/sqlalchemy/engine/default.py", line 552, in do_execute
    cursor.execute(statement, parameters)
  File "/Library/Python/2.7/site-packages/pymysql/cursors.py", line 170, in execute
    result = self._query(query)
  File "/Library/Python/2.7/site-packages/pymysql/cursors.py", line 328, in _query
    conn.query(q)
  File "/Library/Python/2.7/site-packages/pymysql/connections.py", line 517, in query
    self._affected_rows = self._read_query_result(unbuffered=unbuffered)
  File "/Library/Python/2.7/site-packages/pymysql/connections.py", line 732, in _read_query_result
    result.read()
  File "/Library/Python/2.7/site-packages/pymysql/connections.py", line 1075, in read
    first_packet = self.connection._read_packet()
  File "/Library/Python/2.7/site-packages/pymysql/connections.py", line 657, in _read_packet
    packet_header = self._read_bytes(4)
  File "/Library/Python/2.7/site-packages/pymysql/connections.py", line 707, in _read_bytes
    CR.CR_SERVER_LOST, "Lost connection to MySQL server during query")
OperationalError: (pymysql.err.OperationalError) (2013, 'Lost connection to MySQL server during query')
[SQL: INSERT INTO person (name, age, sex, password, updated_at) VALUES (%(name)s, %(age)s, %(sex)s, %(password)s, %(updated_at)s)]
[parameters: {'age': 25, 'password': 'bde1ec8f0f860d01b1f0945cb777218f70b75c46cabb7bf3272b5b406e79f3a005fe0b43b2afb19e6adaae5b41debf3c3fd933e78f4a47f2b55cb91d6e9c15b1', 'sex': u'Male', 'updated_at': None, 'name': u'rkamil'}]
(Background on this error at: http://sqlalche.me/e/e3q8)
[2020-04-16 18:28:16,191] {/Users/rachmankamil/Python/rest-training-batch-3/day-2.2-database/blueprints/__init__.py:26} WARNING - REQUEST_LOG	{"request": {"client_name": "rkamil", "password": "Kamil1290", "age": 25, "sex": "Male"}, "response": {"message": "Internal Server Error"}}
[2020-04-16 18:29:14,122] {/Users/rachmankamil/Python/rest-training-batch-3/day-2.2-database/blueprints/__init__.py:26} WARNING - REQUEST_LOG	{"request": {"client_name": "rkamil", "password": "Kamil1290", "age": 25, "sex": "Male"}, "response": {"age": 25, "password": "e59686adb71932419aecd45eadfa9eadbd26370cf292562d8728b20275b50c56d2a76614c1bbad7c1cbaaf71c243d711356cce6226b843f1c8bccc0b7667a020", "id": 4, "name": "rkamil", "sex": "Male"}}
[2020-04-16 18:31:46,657] {/Users/rachmankamil/Python/rest-training-batch-3/day-2.2-database/blueprints/__init__.py:26} WARNING - REQUEST_LOG	{"request": {"client_name": "raden", "password": "OKE123", "age": 30, "sex": "Male"}, "response": {"age": 30, "password": "8df7114827a303ea01b1902035eb1e1bab51d6b40d115786f6b2d5b9b0385abea25fec96aa9eb4c5f81cce736e7bb3cc8e0180794ec64c5931ba354b9c23b055", "id": 5, "name": "raden", "sex": "Male"}}
[2020-04-16 18:38:39,877] {/Users/rachmankamil/Python/rest-training-batch-3/day-2.2-database/blueprints/__init__.py:26} WARNING - REQUEST_LOG	{"request": {"client_name": "ajay", "password": "alterraacademy", "age": 22, "sex": "Male"}, "response": {"age": 22, "password": "6ff6dcc42fd8accf27d3b205b6ad526c044ac11d7f614eb6ce1d30998d8904ccc40abafc1af4fad8a4fae36fc2e7a954ed730f094c6106f54ad6bde9ffd68b51", "id": 6, "name": "ajay", "sex": "Male"}}
[2020-04-16 18:42:55,447] {/Users/rachmankamil/Python/rest-training-batch-3/day-2.2-database/blueprints/__init__.py:26} WARNING - REQUEST_LOG	{"request": {"client_name": "oci", "password": "alterraacademy", "age": 22, "sex": "Female"}, "response": {"age": 22, "password": "c40b596f15064f8ca08f47ce898e97c2fa6c33d3ee866ecafca8a29856d5998362a34feac747d974a9f0b156b01eeeaf0fc2bec63c709e1a6cef5dd4697f1424", "id": 7, "name": "oci", "sex": "Female"}}
