[2019-12-17 19:22:25,723] {/Users/rachmankamil/Project/rest-batch3/rest_training/lib/python3.7/site-packages/flask/app.py:1891} ERROR - Exception on /person/7 [PUT]
Traceback (most recent call last):
  File "/Users/rachmankamil/Project/rest-batch3/rest_training/lib/python3.7/site-packages/sqlalchemy/engine/base.py", line 1246, in _execute_context
    cursor, statement, parameters, context
  File "/Users/rachmankamil/Project/rest-batch3/rest_training/lib/python3.7/site-packages/sqlalchemy/engine/default.py", line 581, in do_execute
    cursor.execute(statement, parameters)
  File "/Users/rachmankamil/Project/rest-batch3/rest_training/lib/python3.7/site-packages/pymysql/cursors.py", line 170, in execute
    result = self._query(query)
  File "/Users/rachmankamil/Project/rest-batch3/rest_training/lib/python3.7/site-packages/pymysql/cursors.py", line 328, in _query
    conn.query(q)
  File "/Users/rachmankamil/Project/rest-batch3/rest_training/lib/python3.7/site-packages/pymysql/connections.py", line 517, in query
    self._affected_rows = self._read_query_result(unbuffered=unbuffered)
  File "/Users/rachmankamil/Project/rest-batch3/rest_training/lib/python3.7/site-packages/pymysql/connections.py", line 732, in _read_query_result
    result.read()
  File "/Users/rachmankamil/Project/rest-batch3/rest_training/lib/python3.7/site-packages/pymysql/connections.py", line 1075, in read
    first_packet = self.connection._read_packet()
  File "/Users/rachmankamil/Project/rest-batch3/rest_training/lib/python3.7/site-packages/pymysql/connections.py", line 684, in _read_packet
    packet.check_error()
  File "/Users/rachmankamil/Project/rest-batch3/rest_training/lib/python3.7/site-packages/pymysql/protocol.py", line 220, in check_error
    err.raise_mysql_exception(self._data)
  File "/Users/rachmankamil/Project/rest-batch3/rest_training/lib/python3.7/site-packages/pymysql/err.py", line 109, in raise_mysql_exception
    raise errorclass(errno, errval)
pymysql.err.InternalError: (1054, "Unknown column 'person.book_id' in 'field list'")

The above exception was the direct cause of the following exception:

Traceback (most recent call last):
  File "/Users/rachmankamil/Project/rest-batch3/rest_training/lib/python3.7/site-packages/flask/app.py", line 1949, in full_dispatch_request
    rv = self.dispatch_request()
  File "/Users/rachmankamil/Project/rest-batch3/rest_training/lib/python3.7/site-packages/flask/app.py", line 1935, in dispatch_request
    return self.view_functions[rule.endpoint](**req.view_args)
  File "/Users/rachmankamil/Project/rest-batch3/rest_training/lib/python3.7/site-packages/flask_restful/__init__.py", line 458, in wrapper
    resp = resource(*args, **kwargs)
  File "/Users/rachmankamil/Project/rest-batch3/rest_training/lib/python3.7/site-packages/flask/views.py", line 89, in view
    return self.dispatch_request(*args, **kwargs)
  File "/Users/rachmankamil/Project/rest-batch3/rest_training/lib/python3.7/site-packages/flask_restful/__init__.py", line 573, in dispatch_request
    resp = meth(*args, **kwargs)
  File "/Users/rachmankamil/Project/rest-batch3/day-2.2-database/blueprints/person/resources.py", line 50, in put
    qry = Persons.query.get(id)
  File "/Users/rachmankamil/Project/rest-batch3/rest_training/lib/python3.7/site-packages/sqlalchemy/orm/query.py", line 982, in get
    return self._get_impl(ident, loading.load_on_pk_identity)
  File "/Users/rachmankamil/Project/rest-batch3/rest_training/lib/python3.7/site-packages/sqlalchemy/orm/query.py", line 1094, in _get_impl
    return db_load_fn(self, primary_key_identity)
  File "/Users/rachmankamil/Project/rest-batch3/rest_training/lib/python3.7/site-packages/sqlalchemy/orm/loading.py", line 284, in load_on_pk_identity
    return q.one()
  File "/Users/rachmankamil/Project/rest-batch3/rest_training/lib/python3.7/site-packages/sqlalchemy/orm/query.py", line 3325, in one
    ret = self.one_or_none()
  File "/Users/rachmankamil/Project/rest-batch3/rest_training/lib/python3.7/site-packages/sqlalchemy/orm/query.py", line 3294, in one_or_none
    ret = list(self)
  File "/Users/rachmankamil/Project/rest-batch3/rest_training/lib/python3.7/site-packages/sqlalchemy/orm/query.py", line 3367, in __iter__
    return self._execute_and_instances(context)
  File "/Users/rachmankamil/Project/rest-batch3/rest_training/lib/python3.7/site-packages/sqlalchemy/orm/query.py", line 3392, in _execute_and_instances
    result = conn.execute(querycontext.statement, self._params)
  File "/Users/rachmankamil/Project/rest-batch3/rest_training/lib/python3.7/site-packages/sqlalchemy/engine/base.py", line 982, in execute
    return meth(self, multiparams, params)
  File "/Users/rachmankamil/Project/rest-batch3/rest_training/lib/python3.7/site-packages/sqlalchemy/sql/elements.py", line 287, in _execute_on_connection
    return connection._execute_clauseelement(self, multiparams, params)
  File "/Users/rachmankamil/Project/rest-batch3/rest_training/lib/python3.7/site-packages/sqlalchemy/engine/base.py", line 1101, in _execute_clauseelement
    distilled_params,
  File "/Users/rachmankamil/Project/rest-batch3/rest_training/lib/python3.7/site-packages/sqlalchemy/engine/base.py", line 1250, in _execute_context
    e, statement, parameters, cursor, context
  File "/Users/rachmankamil/Project/rest-batch3/rest_training/lib/python3.7/site-packages/sqlalchemy/engine/base.py", line 1476, in _handle_dbapi_exception
    util.raise_from_cause(sqlalchemy_exception, exc_info)
  File "/Users/rachmankamil/Project/rest-batch3/rest_training/lib/python3.7/site-packages/sqlalchemy/util/compat.py", line 398, in raise_from_cause
    reraise(type(exception), exception, tb=exc_tb, cause=cause)
  File "/Users/rachmankamil/Project/rest-batch3/rest_training/lib/python3.7/site-packages/sqlalchemy/util/compat.py", line 152, in reraise
    raise value.with_traceback(tb)
  File "/Users/rachmankamil/Project/rest-batch3/rest_training/lib/python3.7/site-packages/sqlalchemy/engine/base.py", line 1246, in _execute_context
    cursor, statement, parameters, context
  File "/Users/rachmankamil/Project/rest-batch3/rest_training/lib/python3.7/site-packages/sqlalchemy/engine/default.py", line 581, in do_execute
    cursor.execute(statement, parameters)
  File "/Users/rachmankamil/Project/rest-batch3/rest_training/lib/python3.7/site-packages/pymysql/cursors.py", line 170, in execute
    result = self._query(query)
  File "/Users/rachmankamil/Project/rest-batch3/rest_training/lib/python3.7/site-packages/pymysql/cursors.py", line 328, in _query
    conn.query(q)
  File "/Users/rachmankamil/Project/rest-batch3/rest_training/lib/python3.7/site-packages/pymysql/connections.py", line 517, in query
    self._affected_rows = self._read_query_result(unbuffered=unbuffered)
  File "/Users/rachmankamil/Project/rest-batch3/rest_training/lib/python3.7/site-packages/pymysql/connections.py", line 732, in _read_query_result
    result.read()
  File "/Users/rachmankamil/Project/rest-batch3/rest_training/lib/python3.7/site-packages/pymysql/connections.py", line 1075, in read
    first_packet = self.connection._read_packet()
  File "/Users/rachmankamil/Project/rest-batch3/rest_training/lib/python3.7/site-packages/pymysql/connections.py", line 684, in _read_packet
    packet.check_error()
  File "/Users/rachmankamil/Project/rest-batch3/rest_training/lib/python3.7/site-packages/pymysql/protocol.py", line 220, in check_error
    err.raise_mysql_exception(self._data)
  File "/Users/rachmankamil/Project/rest-batch3/rest_training/lib/python3.7/site-packages/pymysql/err.py", line 109, in raise_mysql_exception
    raise errorclass(errno, errval)
sqlalchemy.exc.InternalError: (pymysql.err.InternalError) (1054, "Unknown column 'person.book_id' in 'field list'")
[SQL: SELECT person.id AS person_id, person.name AS person_name, person.age AS person_age, person.sex AS person_sex, person.created_at AS person_created_at, person.updated_at AS person_updated_at, person.deleted AS person_deleted, person.book_id AS person_book_id 
FROM person 
WHERE person.id = %(param_1)s]
[parameters: {'param_1': '7'}]
(Background on this error at: http://sqlalche.me/e/2j85)
[2019-12-17 19:22:25,752] {/Users/rachmankamil/Project/rest-batch3/day-2.2-database/blueprints/__init__.py:30} WARNING - REQUEST_LOG	{"request": {"name": "Rachman Kamil", "age": 25}, "response": {"message": "Internal Server Error"}}
[2019-12-17 19:24:54,590] {/Users/rachmankamil/Project/rest-batch3/day-2.2-database/blueprints/__init__.py:30} WARNING - REQUEST_LOG	{"request": {"name": "Rachman Kamil", "age": 25}, "response": {"id": 7, "name": "Rachman Kamil", "age": 25, "sex": "", "created_at": "Tue, 17 Dec 2019 19:19:36 -0000"}}
