[2020-04-16 17:21:39,399] {/Library/Python/2.7/site-packages/flask/app.py:1891} ERROR - Exception on /person [POST]
Traceback (most recent call last):
  File "/Library/Python/2.7/site-packages/flask/app.py", line 1949, in full_dispatch_request
    rv = self.dispatch_request()
  File "/Library/Python/2.7/site-packages/flask/app.py", line 1935, in dispatch_request
    return self.view_functions[rule.endpoint](**req.view_args)
  File "/Library/Python/2.7/site-packages/flask_restful/__init__.py", line 458, in wrapper
    resp = resource(*args, **kwargs)
  File "/Library/Python/2.7/site-packages/flask/views.py", line 89, in view
    return self.dispatch_request(*args, **kwargs)
  File "/Library/Python/2.7/site-packages/flask_restful/__init__.py", line 573, in dispatch_request
    resp = meth(*args, **kwargs)
  File "/Users/rachmankamil/Python/rest-training-batch-3/day-2.2-database/blueprints/person/resources.py", line 42, in post
    db.session.commit()
  File "/Library/Python/2.7/site-packages/sqlalchemy/orm/scoping.py", line 162, in do
    return getattr(self.registry(), name)(*args, **kwargs)
  File "/Library/Python/2.7/site-packages/sqlalchemy/orm/session.py", line 1027, in commit
    self.transaction.commit()
  File "/Library/Python/2.7/site-packages/sqlalchemy/orm/session.py", line 494, in commit
    self._prepare_impl()
  File "/Library/Python/2.7/site-packages/sqlalchemy/orm/session.py", line 473, in _prepare_impl
    self.session.flush()
  File "/Library/Python/2.7/site-packages/sqlalchemy/orm/session.py", line 2459, in flush
    self._flush(objects)
  File "/Library/Python/2.7/site-packages/sqlalchemy/orm/session.py", line 2597, in _flush
    transaction.rollback(_capture_exception=True)
  File "/Library/Python/2.7/site-packages/sqlalchemy/util/langhelpers.py", line 68, in __exit__
    compat.reraise(exc_type, exc_value, exc_tb)
  File "/Library/Python/2.7/site-packages/sqlalchemy/orm/session.py", line 2557, in _flush
    flush_context.execute()
  File "/Library/Python/2.7/site-packages/sqlalchemy/orm/unitofwork.py", line 422, in execute
    rec.execute(self)
  File "/Library/Python/2.7/site-packages/sqlalchemy/orm/unitofwork.py", line 589, in execute
    uow,
  File "/Library/Python/2.7/site-packages/sqlalchemy/orm/persistence.py", line 245, in save_obj
    insert,
  File "/Library/Python/2.7/site-packages/sqlalchemy/orm/persistence.py", line 1138, in _emit_insert_statements
    statement, params
  File "/Library/Python/2.7/site-packages/sqlalchemy/engine/base.py", line 988, in execute
    return meth(self, multiparams, params)
  File "/Library/Python/2.7/site-packages/sqlalchemy/sql/elements.py", line 287, in _execute_on_connection
    return connection._execute_clauseelement(self, multiparams, params)
  File "/Library/Python/2.7/site-packages/sqlalchemy/engine/base.py", line 1107, in _execute_clauseelement
    distilled_params,
  File "/Library/Python/2.7/site-packages/sqlalchemy/engine/base.py", line 1248, in _execute_context
    e, statement, parameters, cursor, context
  File "/Library/Python/2.7/site-packages/sqlalchemy/engine/base.py", line 1466, in _handle_dbapi_exception
    util.raise_from_cause(sqlalchemy_exception, exc_info)
  File "/Library/Python/2.7/site-packages/sqlalchemy/util/compat.py", line 398, in raise_from_cause
    reraise(type(exception), exception, tb=exc_tb, cause=cause)
  File "/Library/Python/2.7/site-packages/sqlalchemy/engine/base.py", line 1244, in _execute_context
    cursor, statement, parameters, context
  File "/Library/Python/2.7/site-packages/sqlalchemy/engine/default.py", line 552, in do_execute
    cursor.execute(statement, parameters)
  File "/Library/Python/2.7/site-packages/pymysql/cursors.py", line 170, in execute
    result = self._query(query)
  File "/Library/Python/2.7/site-packages/pymysql/cursors.py", line 328, in _query
    conn.query(q)
  File "/Library/Python/2.7/site-packages/pymysql/connections.py", line 517, in query
    self._affected_rows = self._read_query_result(unbuffered=unbuffered)
  File "/Library/Python/2.7/site-packages/pymysql/connections.py", line 732, in _read_query_result
    result.read()
  File "/Library/Python/2.7/site-packages/pymysql/connections.py", line 1075, in read
    first_packet = self.connection._read_packet()
  File "/Library/Python/2.7/site-packages/pymysql/connections.py", line 684, in _read_packet
    packet.check_error()
  File "/Library/Python/2.7/site-packages/pymysql/protocol.py", line 220, in check_error
    err.raise_mysql_exception(self._data)
  File "/Library/Python/2.7/site-packages/pymysql/err.py", line 109, in raise_mysql_exception
    raise errorclass(errno, errval)
IntegrityError: (pymysql.err.IntegrityError) (1062, u"Duplicate entry 'kamil' for key 'name'")
[SQL: INSERT INTO person (name, age, sex, password, updated_at) VALUES (%(name)s, %(age)s, %(sex)s, %(password)s, %(updated_at)s)]
[parameters: {'age': 12, 'password': '5a2155c0a27a6238e6684d4ed501a62cbc2ce8c30f1aad632847fbb86a788070bd4e25a024d5a314f95e61bf8f44c6699b8de1d4379141636ddcdb4eaf606f04', 'sex': u'Male', 'updated_at': None, 'name': u'kamil'}]
(Background on this error at: http://sqlalche.me/e/gkpj)
[2020-04-16 17:21:39,432] {/Users/rachmankamil/Python/rest-training-batch-3/day-2.2-database/blueprints/__init__.py:30} WARNING - REQUEST_LOG	{"request": {"client_name": "kamil", "password": "Kamil1234", "age": 12, "sex": "Male"}, "response": {"message": "Internal Server Error"}}
[2020-04-16 17:21:57,786] {/Users/rachmankamil/Python/rest-training-batch-3/day-2.2-database/blueprints/__init__.py:30} WARNING - REQUEST_LOG	{"request": {"client_name": "rachmankamil", "password": "Kamil1234", "age": 12, "sex": "Male"}, "response": {"age": 12, "password": "e755c6c3591f722fe2fba067c3e9905f739faa1a7f0dd64251d2a1e2141eff69db11df1a831e96c9f9cf946fb33f071e86e88189f1fb43f21fbd35925f6e2107", "id": 3, "name": "rachmankamil", "sex": "Male"}}
